Workbook
Name _Hlk88472928: ' BALANCE 2021'!$I$71
Name _Hlk88473137: ' BALANCE 2021'!$B$84

Sheet PAGE DE GARDE 1
A17: ANIMAL CITY CARE
A23: SARL au Capital de 20 000 DT
A25: Siège Social : 005 RESIDENCE HORIZON BLOC B, AIN ZAGHAOUAN
A26: 2046
A27: MF: 1684120Q/A/M/000
A56: Etats financiers Arrêtés au 31 AOUT 2021

Sheet PAGE DE GARDE 2
A23: Etats financiers Arrêtés au 31 AOUT 2021
A25: ANIMAL CITY CARE
A27: MF: 1684120Q/A/M/000

Sheet  BALANCE 2021
A1: COMPTE | B1: LIBELLE | C1: SD | D1: SC | E1: SOLDE | F1: AFFECTATION
A2: 101100 | B2: CAPITAL SOCIAL | D2: 20000 | E2: -20000 | F2: P1
A3: 121000 | B3: RESULTATS REPORTES | C3: 16057.703 | E3: 16057.703 | F3: P3
A4: 161800 | B4: CTR LEASING 00389940 SEAT | C4: 32368.817 | D4: 92121.425 | E4: -59752.608 | F4: P4
A5: 161801 | B5: CTR LEASING 1577900 | C5: 68293.966 | D5: 125650.21 | E5: -57356.248 | F5: P4
A6: 224400 | B6: MATERIEL DE TRANSPORT DE PERS. | C6: 217771.64 | E6: 217771.64 | F6: A3
A7: 228100 | B7: INST.GENE. AGENC. ET AMENAG J.C | C7: 18364.86 | E7: 18364.86 | F7: A3
A8: 228101 | B8: INST.GENE. AGENC. ET AMENAG JM | C8: 16668.933 | E8: 16668.933 | F8: A3
A9: 228200 | B9: EQUIPEMENT DE BUREAU J.C | C9: 988.696 | E9: 988.696 | F9: A3
A10: 265500 | B10: CAUTIONNEMENTS VERSES | C10: 12942.77 | E10: 12942.77 | F10: A5
A11: 272000 | B11: CHARGES A REPARTIR | C11: 16666.667 | D11: 8333.333 | E11: 8333.334 | F11: A7
A12: 282440 | B12: AMORTI MATERIEL TRANSPORT PERSONNES | D12: 20856.501 | E12: -20856.501 | F12: A4
A13: 282810 | B13: AMORTIS INST GENE AG. AM. DIVERS JC | D13: 4584.783 | E13: -4584.783 | F13: A4
A14: 282811 | B14: AMORTIS INST GENE AG. AM. DIVERS JM | D14: 5699.983 | E14: -5699.983 | F14: A4
A15: 282820 | B15: AMORTISSEMENT EQUIPEMENT BUREAU JC | D15: 296.587 | E15: -296.587 | F15: A4
A16: 370000 | B16: STOCKS DE MARCHANDISES J.M | C16: 73446.937 | D16: 41262.181 | E16: 32184.756 | F16: A8
A17: 370100 | B17: STOCKS DE MARCHANDISES J.C | C17: 179215.8 | D17: 69475.27 | E17: 109740.53 | F17: A8
A18: 401000 | B18: FOURNISSEURS BIENS ET SERVICES | C18: 1018787.4 | D18: 1178083.5 | E18: -159296.1 | F18: P7
A19: 411000 | B19: CLIENT DIVERS | C19: 946142.46 | D19: 943061.38 | E19: 3081.08 | F19: A10
A20: 425000 | B20: PERSONNEL - REMUNERATIONS DUES | C20: 4876.923 | D20: 9145.614 | E20: -4268.691 | F20: P8
A21: 434300 | B21: IMPOT A LIQUIDER | C21: 500 | D21: 23646.37 | E21: -23146.37 | F21: P8
A22: 434301 | B22: CSS / STE | C22: 200 | D22: 1773.091 | E22: -1573.091 | F22: P8
A23: 436670 | B23: CREDIT DE TVA A REPORTER | C23: 320053.6 | D23: 205826.61 | E23: 114226.99 | F23: A12
A24: 448100 | B24: ASSOCIES - OPERATIONS COURANTES | C24: 61111.1 | D24: 232100.07 | E24: -170988.97 | F24: P8
A25: 453110 | B25: CNSS | C25: 1093.011 | D25: 4070.602 | E25: -2977.591 | F25: P8
A26: 457100 | B26: RF IMPOTS ET TAXE A PAYER | C26: 17391.55 | D26: 23286.877 | E26: -5895.327 | F26: P8
A27: 471000 | B27: CHARGES CONSTATEES D'AVANCE | C27: 18417.982 | D27: 13923 | E27: 4494.982 | F27: A12
... A35: 603701 | B35: VAR. STOCKS DE MARCHANDISES J.C | C35: 69475.27 | D35: 109740.53 | E35: -40265.259 | F35: R4
A36: 606002 | B36: ACHATS NON STOCKES ELECTRICITE | C36: 1029.031 | E36: 1029.031 | F36: R4
A37: 607000 | B37: ACHATS DE MARCHANDISES J.M | C37: 153124.7 | D37: 20305.654 | E37: 132819.05 | F37: R4
A38: 607003 | B38: ACHATS NON STOCKES EAU J.C | C38: 17100.988 | E38: 17100.988 | F38: R4
A39: 607006 | B39: ACHAT FOURNITURE ADMINISTRATIVE JM | C39: 152 | E39: 152 | F39: R4
A40: 607100 | B40: ACHATS DE MARCHANDISES J.C | C40: 446641.64 | D40: 29232.042 | E40: 417409.6 | F40: R4
A41: 613010 | B41: LOCATION J.M | C41: 27356.4 | E41: 27356.4 | F41: R7
A42: 613020 | B42: LOCATION J.C | C42: 60725.4 | E42: 60725.4 | F42: R7
A43: 616000 | B43: PRIMES D'ASSURANCES | C43: 4016.749 | E43: 4016.749 | F43: R7
A44: 622100 | B44: FRAIS DE TENUE DE COMPTABILITE | C44: 4400 | E44: 4400 | F44: R7
A45: 626100 | B45: COMMUNICATIONS TELECOM | C45: 1885.95 | E45: 1885.95 | F45: R7
A46: 627000 | B46: SERVICES BANCAIRES ET ASSIMILES | C46: 9821.12 | D46: 980.568 | E46: 8840.552 | F46: R7
A47: 632000 | B47: PENALITE DE RETARD | C47: 523.794 | E47: 523.794 | F47: R8
...

Sheet TCD
A1: Étiquettes de lignes | B1: Somme de SOLDE
A2: A10 | B2: 3081.08
A3: A12 | B3: 118721.97
A4: A15 | B4: 136145.09
A5: A3 | B5: 253794.13
A6: A4 | B6: -31437.854
A7: A5 | B7: 12942.77
A8: A7 | B8: 8333.334
A9: A8 | B9: 141925.29
A10: P1 | B10: -20000
A11: P3 | B11: 16057.703
A12: P4 | B12: -117108.86
A13: P7 | B13: -159296.1
... A26: Total général | B26: -3.6752112e-10

Sheet ACTIF
C2: ANIMAL CITY
C4: BILANS COMPARES ARRETES AUX 31 Déc 2025 & 31 Déc 2024
C6: (En dinars tunisiens)
E9: ACTIFS | F9: Notes | I9: 46022 | L9: 45657
C11: ACTIFS NON COURANTS
D13: Actifs immobilisés
A15: A1 | E15: Immobilisations incorporelles | I15: 45000 | L15: 45000 | M15: =+L15-I15 -> 0
A16: A2 | E16: Moins : amortissements | I16: =IFERROR(VLOOKUP(A16,#REF!,2,0),0) -> 0 | L16: 0
I17: =+I15-I16 -> 45000 | L17: =+L15 -> 45000
I18: =-IFERROR(VLOOKUP(A18,#REF!,2,0),0) -> 0 | L18: 0
A19: A3 | E19: Immobilisations corporelles | I19: 341505 | L19: 338344 | M19: =+I19-L19 -> 3161 | O19: =+I20-L20 -> -66450
A20: A4 | E20: Moins : amortissements | I20: -272194 | L20: -205744 | M20: =+L20-I20 -> 66450
F21: 3.1 | I21: =+I20+I19 -> 69311 | L21: =+L19+L20 -> 132600 | M21: =+L21-I21 -> 63289
E24: Immobilisations encours
I25: =SUM(I24) -> 0 | L25: 0
S26: 31635 | T26: =+L21 -> 132600
A27: A5 | E27: Immobilisations financières | I27: 14293 | L27: 14293 | M27: =+I27-L27 -> 0 | S27: 16667 | T27: =+L33 -> 0
A28: A6 | E28: Moins : provisions | I28: =-IFERROR(VLOOKUP(A28,#REF!,2,0),0) -> 0 | L28: 0 | S28: =SUM(S26:S27) -> 48302 | T28: =SUM(T26:T27) -> 132600
I29: =SUM(I27:I28) -> 14293 | L29: =+L27 -> 14293 | T29: 56635
D31: Total des actifs immobilisés | I31: =+I29+I21+I17 -> 128604 | L31: =+L21+L29+L17 -> 191893 | T31: =+T29-T28 -> -75965
T32: 9143
A33: A7 | E33: Autres actifs non courants | I33: 0 | M33: =+I33-L33 -> 0 | T33: =+T31-T32 -> -85108
I34: =IFERROR(VLOOKUP(A34,#REF!,2,0),0) -> 0 | L34: 0
C35: TOTAL DES ACTIFS NON COURANTS | I35: =+I31 -> 128604 | L35: =+L33+L31 -> 191893
C37: ACTIFS COURANTS
I38: =-IFERROR(VLOOKUP(A38,#REF!,2,0),0) -> 0 | L38: 0
A39: A8 | E39: Stocks | I39: 100385 | L39: 89120 | M39: =+L39-I39 -> -11265
A40: A9 | E40: Moins : provisions | I40: =-IFERROR(VLOOKUP(A40,#REF!,2,0),0) -> 0 | L40: 0
I41: =+I39-I40 -> 100385 | L41: =+L39 -> 89120 | S41: 273114
I42: =-IFERROR(VLOOKUP(A42,#REF!,2,0),0) -> 0 | L42: 0 | S42: -257682
A43: A10 | E43: Clients et comptes rattachés | I43: 8851 | L43: 3846 | M43: =+L43-I43 -> -5005 | S43: -58800
A44: A11 | E44: Moins : provisions
F45: 3.2 | I45: =+I43-I44 -> 8851 | L45: =SUM(L42:L44) -> 3846
I46: =-IFERROR(VLOOKUP(A46,#REF!,2,0),0) -> 0 | L46: 0
A47: A12 | E47: Autres actifs courants | I47: 90128 | L47: 83521 | M47: =+L47-I47 -> -6607
A48: A13 | E48: Moins : provisions
F49: 3.3 | I49: =+I47-I48 -> 90128 | L49: =+L47 -> 83521
A51: A14 | E51: Placements et autres actifs financiers
I52: =-IFERROR(VLOOKUP(A52,#REF!,2,0),0) -> 0 | L52: 0
A53: A15 | E53: Liquidités et équivalents de liquidités | F53: 3.4 | I53: 266952 | L53: 111764 | M53: =+I53-L53 -> 155188
...

Sheet PASSIF
A3: =+ACTIF!C2 -> ANIMAL CITY
A5: BILANS COMPARES ARRETES AUX 31 Déc 2025 & 31 Déc 2024
A7: (En dinars tunisiens)
B10: CAPITAUX PROPRES ET PASSIFS | E10: Notes | H10: =+ACTIF!I9 -> 46022 | J10: 45657
B12: CAPITAUX PROPRES ET PASSIFS
C14: Capitaux propres
A16: P1 | D16: Capital Social | H16: =-VLOOKUP(A16,TCD!A:B,2,0) -> 20000 | J16: 20000
A17: P2 | D17: Réserves | H17: 2000 | J17: 2000 | K17: 2000
A18: P3 | D18: Résultats reportés | H18: 1418 | J18: 18609 | K18: =+H18-J18 -> -17191
H19: =IFERROR(VLOOKUP(A19,#REF!,2,0),0) -> 0 | J19: 0
D20: Total capitaux propres avant résultat | H20: =SUM(H16:H19) -> 23418 | J20: =SUM(J16:J19) -> 40609
D22: Résultat de l'exercice | H22: 98370 | J22: 22809 | K22: =+H22-J22 -> 75561
B24: TOTAL CAPITAUX PROPRES | E24: 4.1 | H24: =+H20+H22 -> 121788 | J24: =+J20+J22 -> 63418 | K24: =+H24-J24 -> 58370
B27: PASSIFS
C29: Passifs non courants
A31: P4 | D31: Emprunts | H31: 19533 | J31: 49600 | L31: =+H31-J31 -> -30067
A32: P5 | D32: Autres passifs financiers | H32: =IFERROR(VLOOKUP(A32,#REF!,2,0),0) -> 0 | J32: 0
A33: P6 | D33: Provisions | H33: =IFERROR(VLOOKUP(A33,#REF!,2,0),0) -> 0 | J33: 0
H34: =IFERROR(VLOOKUP(A34,#REF!,2,0),0) -> 0 | J34: 0
C35: Total passifs non courants | H35: =+H31 -> 19533 | J35: =+J31 -> 49600
H36: =IFERROR(VLOOKUP(A36,#REF!,2,0),0) -> 0 | J36: 0 | Q36: 17365 | R36: 57569
C37: Passifs courants | H37: =IFERROR(VLOOKUP(A37,#REF!,2,0),0) -> 0 | J37: 0 | R37: =+R36-Q36 -> 40204
H38: =IFERROR(VLOOKUP(A38,#REF!,2,0),0) -> 0 | J38: 0
A39: P7 | D39: Fournisseurs et comptes rattachés | E39: 4.2 | H39: 311992 | J39: 259986 | K39: =+H39+H40-J39-J40 -> 102633 | L39: =+H39-J39 -> 52006
A40: P8 | D40: Autres passifs courants | E40: 4.3 | H40: 109723 | J40: 59096 | K40: =+J39+J40-H39-H40 -> -102633 | L40: =+H40-J40 -> 50627
A41: P9 | D41: Concours bancaires et autres passifs financiers | H41: =31883+1 -> 31884 | J41: 48044 | K41: =+H41-J41 -> -16160 | L41: =+H41-J41 -> -16160
C43: Total passifs courants | H43: =SUM(H39:H42) -> 453599 | J43: =SUM(J37:J42) -> 367126
B46: TOTAL DES PASSIFS | H46: =+H43+H35 -> 473132 | J46: =+J35+J43 -> 416726
B50: TOTAL DES CAPITAUX PROPRES ET PASSIFS | H50: =+H46+H24 -> 594920 | J50: =+J24+J46 -> 480144
H51: =+H50-ACTIF!I58 -> 0

Sheet RT
B2: =+PASSIF!A3 -> ANIMAL CITY
B4: ETATS DE RESULTATS COMPARES ARRETES AUX 31 Déc 2025 & 31 Déc 2024
B6: (En dinars tunisiens)
E9: Notes | H9: =+PASSIF!H10 -> 46022 | I9: 45657
B11: PRODUITS D'EXPLOITATION
H12: =IFERROR(VLOOKUP(A12,#REF!,2,0),0) -> 0 | I12: 0
A13: R1 | D13: Revenus | E13: 5.1 | H13: 1837959 | I13: 1600954
A14: R2 | D14: Autres produits d'exploitation
A15: R3 | D15: Production immobilisée | H15: =IFERROR(VLOOKUP(A15,#REF!,2,0),0) -> 0 | I15: 0
D16: Transfert de charges
C17: Total des produits d'exploitation | H17: =+H13+H16 -> 1837959 | I17: =+I13 -> 1600954
H18: =IFERROR(VLOOKUP(A18,#REF!,2,0),0) -> 0 | I18: 0
B19: CHARGES D'EXPLOITATION | H19: =IFERROR(VLOOKUP(A19,#REF!,2,0),0) -> 0 | I19: 0
H20: =IFERROR(VLOOKUP(A20,#REF!,2,0),0) -> 0 | I20: 0
D21: Coût d'achat des marchandises vendues | E21: 5.2 | H21: 1289616 | I21: 1162054 | J21: =+H13/H21 -> 1.4251987 | K21: =+I13/I21 -> 1.3776933 | L21: MARGE
A22: R5 | D22: Charges de personnel | H22: 71935 | I22: 70609
A23: R6 | D23: Dotations aux amortissements et provisions | E23: 5.3 | H23: 66450 | I23: 65973
A24: R7 | D24: Autres charges d'exploitation | E24: 5.4 | H24: 272697 | I24: 251907
C25: Total des charges d'exploitation | H25: =SUM(H21:H24) -> 1700698 | I25: =SUM(I20:I24) -> 1550543
B28: Résultat d'exploitation | H28: =+H17-H25 -> 137261 | I28: =+I17-I25 -> 50411
H29: =IFERROR(VLOOKUP(A29,#REF!,2,0),0) -> 0 | I29: 0
A30: R8 | D30: Charges financières nettes | H30: -13053 | I30: -21476
A31: R9 | D31: Produits des placements | H31: 0
A32: R10 | D32: Autres gains ordinaires
A33: R11 | D33: Autres pertes ordinaires
H34: =IFERROR(VLOOKUP(A34,#REF!,2,0),0) -> 0 | I34: 0
B35: Résultat des activités ordinaires avant impôt | H35: =H28+H30+H32+H33 -> 124208 | I35: =SUM(I28:I33) -> 28935
A37: R12 | D37: Impôt sur les bénéfices | H37: -25838 | I37: -6126
B39: Résultat des activités ordinaires après impôt | H39: =SUM(H35:H38) -> 98370 | I39: =SUM(I35:I37) -> 22809
A41: R13 | D41: Eléments extraordinaires
B43: Résultat net de l'exercice | H43: =+H39-H41 -> 98370 | I43: =+I39 -> 22809
A45: R14 | D45: Effets des modifications comptables
B47: Résultat après modifications comptables | H47: =+H43-H45 -> 98370 | I47: =+I43 -> 22809

Sheet FLUX
B2: =+RT!B2 -> ANIMAL CITY
B4: ETATS DES FLUX DE TRESORERIE COMPARES ARRETES AUX 31 Déc 2025 & 31 Déc 2024
B6: (En dinars tunisiens)
F9: Notes | H9: =+'SIG '!F8 -> 46022 | I9: 45657
B11: Flux de trésorerie liés à l'exploitation
C13: Résultat net | H13: =+RT!H47 -> 98370 | I13: 22810
C14: Ajustements pour : | H14: =IFERROR(VLOOKUP(A14,#REF!,2,0),0) -> 0
A15: R1 | D15: Amortissements et provisions | H15: =+RT!H23 -> 66450 | I15: 65973
D16: Variation des : | H16: =IFERROR(VLOOKUP(A16,#REF!,2,0),0) -> 0 | I16: 0
A17: R2 | E17: - Stocks | H17: =-ACTIF!I39+ACTIF!L39 -> -11265 | I17: 49516
A18: R3 | E18: - Créances | H18: =-ACTIF!I43+ACTIF!L43 -> -5005 | I18: 93
A19: R4 | E19: - Autres actifs | H19: =-ACTIF!I47+ACTIF!L47 -> -6607 | I19: 107496
A20: R5 | E20: - Fournisseurs et autres dettes | H20: =PASSIF!H43-PASSIF!J43+1425 -> 87898 | I20: 35895
A21: R6 | D21: Plus ou moins values de cession
A22: R7 | D22: Reprise sur provision | H22: =IFERROR(VLOOKUP(A22,#REF!,2,0),0) -> 0 | I22: 0
H23: =IFERROR(VLOOKUP(A23,#REF!,2,0),0) -> 0 | I23: 0
B24: Flux de trésorerie liés à l'exploitation | H24: =SUM(H13:H23) -> 229841 | I24: =SUM(I13:I20) -> 281783
B26: Flux de trésorerie liés aux activités d'investissement
A28: R8 | D28: Acquisitions d'immobilisations | H28: =+ACTIF!L19-ACTIF!I19 -> -3161 | I28: -5303
A29: R9 | D29: Cessions d'immobilisations | H29: =IFERROR(VLOOKUP(A29,#REF!,2,0),0) -> 0 | I29: 0
A30: R10 | D30: Cession de titres de placements | H30: =IFERROR(VLOOKUP(A30,#REF!,2,0),0) -> 0 | I30: 0
A31: R11 | D31: Autres Immo Financieres
H32: =IFERROR(VLOOKUP(A32,#REF!,2,0),0) -> 0 | I32: 0
B33: Flux de trésorerie liés aux activités d'investissement | H33: =SUM(H25:H32) -> -3161 | I33: =+I28+I31 -> -5303
B35: Flux de trésorerie liés aux activités de financement
A37: R12 | D37: Encaissements liés au capital
A38: R13 | D38: Dividendes et autres distributions | H38: -40000 | I38: -160000
A39: R14 | D39: Encaissements provenant des emprunts
A40: R15 | D40: Remboursements d'emprunts | H40: =+PASSIF!H31-PASSIF!J31 -> -30067 | I40: -38255
B42: Flux de trésorerie liés aux activités de financement | H42: =SUM(H37:H41) -> -70067 | I42: =SUM(I38:I41) -> -198255
A44: R16 | D44: Incidence des variations des taux de change sur les
A45: R17 | D45: liquidités et équivalents de liquidités
B47: Variation de trésorerie | H47: =+H24+H33+H42+H45 -> 156613 | I47: =+I24+I33+I42 -> 78225
D49: Trésorerie au début de l'exercice | H49: 110339 | I49: 32114
D50: Trésorerie à la clôture de l'exercice | H50: =+ACTIF!I53 -> 266952 | I50: 110339 | K50: =+I50-H49 -> 0
B52: Variation de trésorerie | H52: =H50-H49 -> 156613 | I52: =+I50-I49 -> 78225
H53: =+H47-H52 -> 0
H55: =+H53/2 -> 0

Sheet SIG 
A2: =+FLUX!B2 -> ANIMAL CITY
A4: SOLDES INTERMEDIAIRES DE GESTION COMPARES ARRETES AUX 31 Déc 2025 & 31 Déc 2024
A6: (En dinars tunisiens)
D8: Notes | F8: =+RT!H9 -> 46022 | G8: 45291
B10: Ventes de marchandises | F10: =+RT!H13 -> 1837959 | G10: 1600954
B11: Cout d'achat des Mses Vendues
A13: MARGE COMMERCIALE | F13: =SUM(F10:F12) -> 1837959 | G13: =+G10+G11 -> 1600954
B15: Revenus et autres produits d'exploitation
B16: Production stockée
B17: Production immobilisée
B18: =+RT!D16 -> Transfert de charges
A19: PRODUCTION DE L'EXERCICE
B21: Coût d'achat des marchandises vendues | F21: =-RT!H21 -> -1289616 | G21: =-RT!I21 -> -1162054
A24: MARGE COMMERCIALE | F24: =+F13+F22+F21 -> 548343 | G24: =+G22+G21+G13 -> 438900
A26: ACTIVITE TOTALE | F26: =+F24 -> 548343 | G26: =+G24 -> 438900
B28: Marge brute totale | F28: =+F24 -> 548343 | G28: 438900
B29: Achats d'approvisionnements consommés
B30: Autres charges externes | F30: =-292765+25838 -> -266927 | G30: -245978
A32: VALEUR AJOUTEE BRUTE | F32: =+F26+F30 -> 281416 | G32: =+G30+G26 -> 192922
B34: Impôts et taxes | F34: -5770 | G34: -5929
B35: Charges de personnel | F35: =-RT!H22 -> -71935 | G35: -70609
A37: EXCEDENT BRUT D'EXLOITATION | F37: =SUM(F32:F36) -> 203711 | G37: =SUM(G32:G35) -> 116384
B39: Charges financières nettes | F39: =+RT!H30 -> -13053 | G39: -21476
B40: Produits des placements
B41: Autres gains ordinaires
B42: Autres pertes ordinaires
B43: Transfert et reprise de charges
B44: Dotation aux amortissements et aux provisions | F44: =-RT!H23 -> -66450 | G44: -65973
B45: Impôt sur le résultat ordinaire | F45: -25838 | G45: -6126
A47: RESULTAT DES ACTIVITES ORDINAIRES | F47: =SUM(F37:F46) -> 98370 | G47: =SUM(G37:G45) -> 22809
B49: Eléments extraordinaires net d'impôt
B50: Effets des modifications comptables net d'impôt
A52: Résultat net après modifications comptables | F52: =+F47 -> 98370 | G52: =+G47 -> 22809

Sheet RESULTAT FISCAL
A3: TABLEAU DE DÉTERMINATION DU RÉSULTAT FISCAL 2025
B8: Résultat comptable | F8: 98370.262
B10: Réintégrations: | F10: =SUM(F11:F15) -> 30821.724
C12: Impôts sur le résultat | F12: 25838.397
C13: Css | F13: 3875.76
C14: Timbres de voyage
C15: Pénalités de retard | F15: 1107.567
C16: Dotations aux provision sur indemnités de mise à la retraite | F16: 0
C17: Charges non déductibles
C18: pertes exceptionnelles
C19: factures non en bonne et due forme
C20: Dotations aux provisions pour congés payés | F20: 0
C21: Dotations aux resorption des charges
C22: Reprise gain de change sur réévaluation | F22: 0
C23: Pertes de change sur réévaluations
F24: 0
B25: Déductions: | F25: =SUM(F26:F27) -> 0
C26: Reprise de la perte de change sur réévaluation | F26: 0
C27: Gain de change sur réévaluation
B29: Résultat fiscal | F29: =+F8+F10+F25 -> 129191.99
B30: Résultat imposable | F30: =+F29 -> 129191.99
B32: Impôt sur les sociétés 2025 | F32: =F30*0.2 -> 25838.397
B33: Acompte provisionnel
B34: report d impot 2024 | F34: 64184.059
B35: Retenue à la source / clients | F35: 106.085
B36: Reports IS ® | F36: =+F34+F35-F32 -> 38451.747
B37: CSS 2025 | F37: =+F29*3% -> 3875.7596
B38: report CSS 2024 | F38: 6768.811
B39: Repport CSS 2025 | F39: =+F38-F37 -> 2893.0514

Sheet TAB AMT
A1: ANIMAL CITY
A3: TABLEAU DE VARIATION DES IMMOBILISATIONS ET DES AMORTISSEMENTS AUX 31 Décembre 2025
A5: (En dinars tunisiens)
D8: Valeurs brutes | I8: Amortissements | M8: VCN
D9: 45657 | E9: Acquisitions | F9: Reclassement | G9: 46022 | I9: =+D9 -> 45657 | J9: Dotation | K9: Régul | L9: =+G9 -> 46022 | M9: =L9 -> 46022
A11: Immobilisations Incorporelles | D11: =SUM(D13:D13) -> 45000 | E11: =SUM(E13:E13) -> 0 | F11: =SUM(F13:F13) -> 0 | G11: =SUM(G13:G13) -> 45000 | I11: =SUM(I12:I13) -> 0 | J11: =SUM(J12:J13) -> 0 | K11: =SUM(K12:K13) -> 0 | L11: =SUM(L12:L13) -> 0 | M11: =SUM(M13:M13) -> 45000
A13: Fonds Commercial | D13: 45000 | E13: 0 | F13: 0 | G13: 45000 | I13: 0 | J13: 0 | K13: 0 | L13: 0 | M13: 45000
A15: Immobilisations corporelles | D15: =SUM(D17:D30) -> 338344 | E15: =SUM(E16:E30) -> 3161 | F15: =SUM(F16:F16) -> 0 | G15: =SUM(G16:G30) -> 341505 | I15: =SUM(I16:I30) -> 205744 | J15: =SUM(J17:J30) -> 66450 | K15: 0 | L15: =SUM(I15:K15) -> 272194 | M15: =G15-L15 -> 69311
A18: Inst .géne. Agen .et amenagement J.Carthage | D18: 19725 | E18: 0 | F18: 0 | G18: =+D18+E18-F18 -> 19725 | I18: 16013 | J18: 3196 | K18: 0 | L18: =+I18+J18 -> 19209 | M18: =+G18-L18 -> 516
A20: Inst .géne. Agen .et amenagement J.Menzah | D20: 16668 | E20: 0 | F20: 0 | G20: =+D20+E20-F20 -> 16668 | I20: 14670 | J20: 1998 | K20: 0 | L20: =+I20+J20 -> 16668 | M20: =+G20-L20 -> 0
A22: Inst .géne. Agen .et amenagement Carthage | D22: 5000 | E22: 0 | F22: 0 | G22: 5000 | I22: 1000 | J22: 1000 | K22: 0 | L22: =+I22+J22 -> 2000 | M22: =+G22-L22 -> 3000
A24: Equipement de bureau J.Carthage | D24: 12773 | E24: 0 | F24: 0 | G24: =+D24+E24-F24 -> 12773 | I24: 5045 | J24: 2637 | K24: 0 | L24: =+I24+J24 -> 7682 | M24: =+G24-L24 -> 5091
A26: Equipement de bureau J.Menzah | D26: 4323 | E26: 0 | F26: 0 | G26: =+D26+E26-F26 -> 4323 | I26: 1500 | J26: 797 | K26: 0 | L26: =+I26+J26 -> 2297 | M26: =+G26-L26 -> 2026
A28: Matriel Informatique | D28: 4514 | E28: =+G28-D28 -> 1933 | F28: 0 | G28: 6447 | I28: 645 | J28: 1672 | K28: 0 | L28: =+I28+J28 -> 2317 | M28: =+G28-L28 -> 4130
A30: Matériel de transport personnes phisiques | D30: 275341 | E30: =+G30-D30 -> 1228 | G30: 276569 | I30: 166871 | J30: 55150 | K30: 0 | L30: =+I30+J30 -> 222021 | M30: =+G30-L30 -> 54548
D31: =+D15+D11 -> 383344 | E31: =+E15+E11 -> 3161 | F31: 0 | G31: =+G15+G11 -> 386505 | I31: =+I15 -> 205744 | J31: =+J15 -> 66450 | K31: 0 | L31: =+L15 -> 272194 | M31: =+M15+M11 -> 114311
